Workbook

Sheet 01_README
A1: AIDC被动元件量价缺口模型 v2.0
A2: Volume-Price Gap Model for AIDC Passive Components | 2024-2028
A4: 模型版本 | B4: v2.0（基于产业链纪要校准修正）
A5: 建模日期 | B5: 2026年5月
A6: 覆盖品类 | B6: MLCC | 功率电感 | 薄膜电容 | 钽聚合物 | 铝电解 | 超级电容 | 片式电阻
A7: 时间维度 | B7: 2024-2028（5年，含2024-2025历史校准）
A8: 需求颗粒度 | B8: AIDC + GPU/ASIC平台细分（H100/H200/B200/GB200/GB300/Rubin/Rubin Ultra/AMD MI/ASIC）
A9: 供给颗粒度 | B9: 全球Top8原厂分别建模
A11: 工作表结构
A12: Sheet名 | B12: 内容 | C12: 类型
A13: 01_README | B13: 本说明页 | C13: —
A14: 02_Assumptions_GPU | B14: GPU/ASIC平台年度出货预测 | C14: INPUT（黄色单元格可调）
A15: 03_Assumptions_BOM | B15: 各平台被动元件单机用量BOM | C15: INPUT
A16: 04_Assumptions_Supply | B16: 原厂产能与扩产计划 | C16: INPUT
A17: 05_Demand_MLCC | B17: MLCC需求矩阵：平台×年 | C17: CALC（公式联动）
A18: 06_Demand_Inductor | B18: 功率电感需求矩阵 | C18: CALC
A19: 07_Demand_FilmCap | B19: 薄膜电容需求矩阵 | C19: CALC
A20: 08_Demand_Other | B20: 钽聚/铝电解/超容/电阻需求 | C20: CALC
A21: 09_Gap_Analysis | B21: 供需缺口与价格弹性预测 | C21: CALC
A22: 10_Scenarios | B22: 三情景：保守/中性/乐观 | C22: CALC
A23: 11_Sensitivity | B23: 关键变量敏感性分析 | C23: CALC
A24: 12_Investment_Map | B24: 标的弹性测算（海外+国内） | C24: CALC+定性
A26: 颜色图例
A27: 颜色 | B27: 含义
A28: 黄色填充 | B28: INPUT输入单元（可手工调整）
A29: 灰色填充 | B29: CALC公式计算单元（请勿覆盖）
A30: 浅蓝填充 | B30: Total/合计行
A31: 浅红填充 | B31: 供给短缺/负缺口（紧张）
A32: 浅绿填充 | B32: 供给充裕/正缺口（宽松）
A35: 使用说明
A36: ① 在Sheet 02-04的INPUT单元格中调整假设，Sheet 05-09自动重算（若部分单元为静态值，请在Sheet 10/11切换情景）。
A37: ② Sheet 10提供三情景对比；Sheet 11对4个核心驱动变量做弹性测试。
A38: ③ Sheet 12在缺口和涨价基础上推导各龙头的收入/利润弹性，仅供参考。
A39: ④ 模型基于公开信息推算，单点数据可能存在±20%误差，但方向与量级有较强参考价值。
A40: ⑤ 关键不确定性：AI capex斜率、原厂扩产兑现度、贵金属价格、国产替代速度。
A43: v2.0 新增Sheet
A44: 13_Spot_vs_OEM | B44: 现货vs出厂价：传导时滞模型 + 数据可信度A/B/C分级
A45: 14_Catalyst_Calendar | B45: 催化日历：5个关键事件节点 + 板块脉冲实证 + 退出信号清单
A46: 15_Reverse_Scenario | B46: 反向情景：5大杀手 + 标的安全边际矩阵 + 三种组合配置思路
A47: 16_Upstream_Targets | B47: 上游材料层（国瓷/博迁/洁美/铂科）+ 流通环节（商络）专项分析
...

Sheet 02_Assumptions_GPU
A1: 假设页1：GPU/ASIC平台年度出货量预测（万台或万机柜）
A2: 单位：服务器=台（多卡服务器以"台"计），机柜=台（72-144 GPU/柜）
A4: 平台 | B4: 形态 | C4: 卡/柜数 | D4: 2024(千) | E4: 2025(千) | F4: 2026(千) | G4: 2027(千) | H4: 2028(千)
A5: H100 HGX | B5: 8GPU服务器 | C5: 8 | D5: 800 | E5: 200 | F5: 50 | G5: 0 | H5: 0
A6: H200 HGX | B6: 8GPU服务器 | C6: 8 | D6: 200 | E6: 600 | F6: 200 | G6: 50 | H6: 0
A7: B100/B200 HGX | B7: 8GPU服务器 | C7: 8 | D7: 50 | E7: 800 | F7: 600 | G7: 300 | H7: 100
A8: GB200 NVL72 | B8: 整机柜 | C8: 72 | D8: 0 | E8: 30 | F8: 25 | G8: 10 | H8: 0
A9: GB300 NVL72 | B9: 整机柜 | C9: 72 | D9: 0 | E9: 5 | F9: 60 | G9: 30 | H9: 10
A10: Rubin VR200 NVL144 | B10: 整机柜 | C10: 144 | D10: 0 | E10: 0 | F10: 10 | G10: 50 | H10: 80
A11: Rubin Ultra (NVL576) | B11: 整机柜 | C11: 576 | D11: 0 | E11: 0 | F11: 0 | G11: 5 | H11: 40
A12: AMD MI300X | B12: 8GPU服务器 | C12: 8 | D12: 80 | E12: 150 | F12: 100 | G12: 50 | H12: 0
A13: AMD MI325X | B13: 8GPU服务器 | C13: 8 | D13: 0 | E13: 50 | F13: 100 | G13: 50 | H13: 0
A14: AMD MI350 | B14: 8GPU服务器 | C14: 8 | D14: 0 | E14: 30 | F14: 200 | G14: 150 | H14: 50
A15: AMD MI400 | B15: 8GPU服务器 | C15: 8 | D15: 0 | E15: 0 | F15: 50 | G15: 200 | H15: 200
A16: Google TPU v5/v6 | B16: TPU pod服务器 | C16: 8 | D16: 60 | E16: 100 | F16: 150 | G16: 200 | H16: 250
... A18: Meta MTIA / 其他ASIC | B18: ASIC服务器 | C18: 8 | D18: 10 | E18: 40 | F18: 100 | G18: 150 | H18: 250
A19: —— 合计：8GPU服务器（H/B HGX + AMD + ASIC） | D19: =SUM(D5:D6)+SUM(D7:D7)+SUM(D12:D18) | E19: =SUM(E5:E6)+SUM(E7:E7)+SUM(E12:E18) | F19: =SUM(F5:F6)+SUM(F7:F7)+SUM(F12:F18) | G19: =SUM(G5:G6)+SUM(G7:G7)+SUM(G12:G18) | H19: =SUM(H5:H6)+SUM(H7:H7)+SUM(H12:H18)
A20: —— 合计：NVIDIA整机柜（GB200+GB300+Rubin系列） | D20: =SUM(D8:D11) | E20: =SUM(E8:E11) | F20: =SUM(F8:F11) | G20: =SUM(G8:G11) | H20: =SUM(H8:H11)
A22: • 数据来源：TrendForce / Morgan Stanley / Mizuho / SemiAnalysis / Ming-Chi Kuo / 公司公告
A23: • GB200 NVL72 2025年出货预期已从初版50-80K下修至25-35K（取30K中值）
A24: • GB300 NVL72 2026年Morgan Stanley预期60K机柜，2027年随Rubin迁移而回落
A25: • Rubin VR200 NVL144 2026年小批量、2027年放量，2028年Rubin Ultra主力
A26: • AMD MI400 2026年小批量启动，2027-2028年随OpenAI等大客户订单放量
A27: • ASIC含Google TPU v5/v6/v7、AWS Trainium2/3、Meta MTIA、微软Maia等

Sheet 03_Assumptions_BOM
A1: 假设页2：各平台被动元件单机用量BOM
A2: 单位：颗/台或颗/柜（机柜级BOM按完整NVL机柜配置含Compute Tray + Switch Tray + Power Shelf）
A4: 平台 | B4: MLCC(颗) | C4: 其中:高容≥10μF占比 | D4: 功率电感(颗) | E4: 薄膜电容(颗) | F4: 钽聚合物(颗) | G4: 铝电解(颗) | H4: 超级电容(颗) | I4: 片式电阻(颗)
A5: H100 HGX 8GPU服务器 | B5: 5000 | C5: 55% | D5: 250 | E5: 12 | F5: 80 | G5: 60 | H5: 0 | I5: 8000
A6: H200 HGX 8GPU服务器 | B6: 6000 | C6: 58% | D6: 280 | E6: 14 | F6: 100 | G6: 70 | H6: 0 | I6: 9000
A7: B100/B200 HGX 8GPU服务器 | B7: 10000 | C7: 62% | D7: 400 | E7: 25 | F7: 200 | G7: 100 | H7: 2 | I7: 12000
A8: GB200 NVL72 整机柜 | B8: 440000 | C8: 65% | D8: 12000 | E8: 1500 | F8: 8000 | G8: 2500 | H8: 80 | I8: 480000
A9: GB300 NVL72 整机柜 | B9: 550000 | C9: 67% | D9: 15000 | E9: 1800 | F9: 10000 | G9: 3000 | H9: 120 | I9: 600000
A10: Rubin VR200 NVL144 整机柜 | B10: 850000 | C10: 70% | D10: 22000 | E10: 2500 | F10: 14000 | G10: 4000 | H10: 200 | I10: 950000
A11: Rubin Ultra NVL576 整机柜 | B11: 1200000 | C11: 72% | D11: 30000 | E11: 3500 | F11: 18000 | G11: 5500 | H11: 350 | I11: 1400000
A12: AMD MI300X 服务器 | B12: 8000 | C12: 60% | D12: 350 | E12: 18 | F12: 150 | G12: 80 | H12: 0 | I12: 10000
A13: AMD MI325X 服务器 | B13: 9000 | C13: 62% | D13: 380 | E13: 20 | F13: 180 | G13: 90 | H13: 0 | I13: 11000
A14: AMD MI350 服务器 | B14: 12000 | C14: 64% | D14: 450 | E14: 28 | F14: 250 | G14: 110 | H14: 1 | I14: 14000
A15: AMD MI400 服务器 | B15: 15000 | C15: 66% | D15: 600 | E15: 35 | F15: 350 | G15: 140 | H15: 2 | I15: 18000
A16: Google TPU 服务器 | B16: 6000 | C16: 60% | D16: 220 | E16: 15 | F16: 100 | G16: 70 | H16: 0 | I16: 9000
... A19: （参考）传统通用服务器 | B19: 1000 | C19: 20% | D19: 80 | E19: 5 | F19: 30 | G19: 30 | H19: 0 | I19: 1500
A20: • BOM来源：NVIDIA SuperCluster白皮书、SemiAnalysis拆机报告、TrendForce产业链调研
A21: • GB200 NVL72 整机柜MLCC约44万颗为业内多方调研中位数（Murata/三星电机表态、Yano Research）
A22: • GB300相对GB200单机柜增量主要来自更高HBM3e容量、更密集VRM、HVDC电源升级
A23: • Rubin VR200/144 GPU相对GB200/72 GPU翻倍+功率密度上升，BOM按线性外推×1.6
A24: • Rubin Ultra NVL576为概念性预测，单机柜功耗预期600kW+
A25: • 高容值≥10μF占比快速提升来自薄层化+多层化技术持续渗透
A26: • ASIC平台BOM相对GPU平台略低，因为电源拓扑相对简化、PCIe接口更少

Sheet 04_Assumptions_Supply
A1: 假设页3：原厂产能与扩产计划（单位：十亿颗/年）
A2: 聚焦"高端AI/车规"品类产能（非全产能），含高容值小封装MLCC + AIDC级电感 + HVDC薄膜
A4: [A] MLCC 高端品类产能（十亿颗/年）
A5: 原厂 | B5: 2024 | C5: 2025 | D5: 2026 | E5: 2027 | F5: 2028
A6: Murata（村田） | B6: 30 | C6: 35 | D6: 40 | E6: 50 | F6: 65
A7: Samsung Electro-Mechanics | B7: 18 | C7: 22 | D7: 30 | E7: 42 | F7: 55
A8: Taiyo Yuden（太阳诱电） | B8: 10 | C8: 12 | D8: 15 | E8: 20 | F8: 26
A9: TDK | B9: 8 | C9: 9 | D9: 11 | E9: 14 | F9: 18
A10: Yageo（国巨） | B10: 5 | C10: 6 | D10: 8 | E10: 11 | F10: 15
A11: 华新科（Walsin） | B11: 3 | C11: 4 | D11: 5 | E11: 7 | F11: 9
A12: 三环集团（中国） | B12: 1 | C12: 2 | D12: 3 | E12: 5 | F12: 8
A13: 风华高科（中国） | B13: 1 | C13: 1.5 | D13: 2.5 | E13: 4 | F13: 7
A14: 其他厂商 | B14: 4 | C14: 5 | D14: 7 | E14: 10 | F14: 13
A15: MLCC 高端总产能 | B15: =SUM(B6:B14) | C15: =SUM(C6:C14) | D15: =SUM(D6:D14) | E15: =SUM(E6:E14) | F15: =SUM(F6:F14)
A17: [B] 高端AI功率电感产能（亿颗/年）
A18: 原厂 | B18: 2024 | C18: 2025 | D18: 2026 | E18: 2027 | F18: 2028
A19: Vishay (IHLP) | B19: 8 | C19: 10 | D19: 12 | E19: 15 | F19: 19
A20: TDK (SPM) | B20: 6 | C20: 7 | D20: 9 | E20: 12 | F20: 16
A21: Murata | B21: 5 | C21: 6 | D21: 8 | E21: 10 | F21: 13
A22: 顺络电子 | B22: 3 | C22: 5 | D22: 8 | E22: 12 | F22: 18
A23: 奇力新 | B23: 4 | C23: 5 | D23: 6 | E23: 8 | F23: 11
A24: 其他 | B24: 6 | C24: 8 | D24: 10 | E24: 13 | F24: 17
A25: 电感高端总产能 | B25: =SUM(B19:B24) | C25: =SUM(C19:C24) | D25: =SUM(D19:D24) | E25: =SUM(E19:E24) | F25: =SUM(F19:F24)
A27: [C] HVDC薄膜电容产能（百万颗/年）
A28: 原厂 | B28: 2024 | C28: 2025 | D28: 2026 | E28: 2027 | F28: 2028
A29: TDK Epcos | B29: 60 | C29: 70 | D29: 90 | E29: 120 | F29: 150
A30: Vishay | B30: 40 | C30: 50 | D30: 65 | E30: 85 | F30: 110
A31: Kemet/Yageo | B31: 30 | C31: 35 | D31: 45 | E31: 60 | F31: 80
A32: Nichicon | B32: 20 | C32: 25 | D32: 32 | E32: 42 | F32: 55
A33: 法拉电子 | B33: 25 | C33: 35 | D33: 55 | E33: 80 | F33: 110
A34: 江海股份 | B34: 8 | C34: 12 | D34: 20 | E34: 32 | F34: 48
A35: 其他 | B35: 30 | C35: 40 | D35: 55 | E35: 75 | F35: 100
A36: 薄膜高端总产能 | B36: =SUM(B29:B35) | C36: =SUM(C29:C35) | D36: =SUM(D29:D35) | E36: =SUM(E29:E35) | F36: =SUM(F29:F35)
A38: • MLCC高端产能假设：仅包含适用于AI/车规的≥10μF小封装、低ESR、高压(≥500V)等品类
A39: • 产能数据为业内估算，2024-2025年为实际值复盘，2026-2028年为基于公开扩产计划的推算
A40: • 三星电机菲律宾Calamba新厂2026Q2投产，对应2026/2027产能跳跃
A41: • Murata 2026年发布50亿日元AI server power module目标，对应高端产能扩产
A42: • 国内三环、风华扩产积极，但有效产能仍需2-3年良率爬坡
A43: • 电感产能含合金粉末模压电感、TLVR耦合电感、垂直供电模块电感
A44: • 薄膜电容产能含金属化PP薄膜、HVDC母线大容量产品

Sheet 05_Demand_MLCC
A1: MLCC需求矩阵（按平台×年，单位：十亿颗）
A2: 需求 = 平台出货量(千) × 单机MLCC用量(颗) ÷ 1,000,000 = 十亿颗
A4: 平台 | B4: 单机MLCC用量(颗) | C4: 2024 | D4: 2025 | E4: 2026 | F4: 2027 | G4: 2028
A5: ='03_Assumptions_BOM'!A5 | B5: ='03_Assumptions_BOM'!B5 | C5: ='02_Assumptions_GPU'!D5*'03_Assumptions_BOM'!B5/1000000 | D5: ='02_Assumptions_GPU'!E5*'03_Assumptions_BOM'!B5/1000000 | E5: ='02_Assumptions_GPU'!F5*'03_Assumptions_BOM'!B5/1000000 | F5: ='02_Assumptions_GPU'!G5*'03_Assumptions_BOM'!B5/1000000 | G5: ='02_Assumptions_GPU'!H5*'03_Assumptions_BOM'!B5/1000000
A6: ='03_Assumptions_BOM'!A6 | B6: ='03_Assumptions_BOM'!B6 | C6: ='02_Assumptions_GPU'!D6*'03_Assumptions_BOM'!B6/1000000 | D6: ='02_Assumptions_GPU'!E6*'03_Assumptions_BOM'!B6/1000000 | E6: ='02_Assumptions_GPU'!F6*'03_Assumptions_BOM'!B6/1000000 | F6: ='02_Assumptions_GPU'!G6*'03_Assumptions_BOM'!B6/1000000 | G6: ='02_Assumptions_GPU'!H6*'03_Assumptions_BOM'!B6/1000000
A7: ='03_Assumptions_BOM'!A7 | B7: ='03_Assumptions_BOM'!B7 | C7: ='02_Assumptions_GPU'!D7*'03_Assumptions_BOM'!B7/1000000 | D7: ='02_Assumptions_GPU'!E7*'03_Assumptions_BOM'!B7/1000000 | E7: ='02_Assumptions_GPU'!F7*'03_Assumptions_BOM'!B7/1000000 | F7: ='02_Assumptions_GPU'!G7*'03_Assumptions_BOM'!B7/1000000 | G7: ='02_Assumptions_GPU'!H7*'03_Assumptions_BOM'!B7/1000000
A8: ='03_Assumptions_BOM'!A8 | B8: ='03_Assumptions_BOM'!B8 | C8: ='02_Assumptions_GPU'!D8*'03_Assumptions_BOM'!B8/1000000 | D8: ='02_Assumptions_GPU'!E8*'03_Assumptions_BOM'!B8/1000000 | E8: ='02_Assumptions_GPU'!F8*'03_Assumptions_BOM'!B8/1000000 | F8: ='02_Assumptions_GPU'!G8*'03_Assumptions_BOM'!B8/1000000 | G8: ='02_Assumptions_GPU'!H8*'03_Assumptions_BOM'!B8/1000000
A9: ='03_Assumptions_BOM'!A9 | B9: ='03_Assumptions_BOM'!B9 | C9: ='02_Assumptions_GPU'!D9*'03_Assumptions_BOM'!B9/1000000 | D9: ='02_Assumptions_GPU'!E9*'03_Assumptions_BOM'!B9/1000000 | E9: ='02_Assumptions_GPU'!F9*'03_Assumptions_BOM'!B9/1000000 | F9: ='02_Assumptions_GPU'!G9*'03_Assumptions_BOM'!B9/1000000 | G9: ='02_Assumptions_GPU'!H9*'03_Assumptions_BOM'!B9/1000000
A10: ='03_Assumptions_BOM'!A10 | B10: ='03_Assumptions_BOM'!B10 | C10: ='02_Assumptions_GPU'!D10*'03_Assumptions_BOM'!B10/1000000 | D10: ='02_Assumptions_GPU'!E10*'03_Assumptions_BOM'!B10/1000000 | E10: ='02_Assumptions_GPU'!F10*'03_Assumptions_BOM'!B10/1000000 | F10: ='02_Assumptions_GPU'!G10*'03_Assumptions_BOM'!B10/1000000 | G10: ='02_Assumptions_GPU'!H10*'03_Assumptions_BOM'!B10/1000000
A11: ='03_Assumptions_BOM'!A11 | B11: ='03_Assumptions_BOM'!B11 | C11: ='02_Assumptions_GPU'!D11*'03_Assumptions_BOM'!B11/1000000 | D11: ='02_Assumptions_GPU'!E11*'03_Assumptions_BOM'!B11/1000000 | E11: ='02_Assumptions_GPU'!F11*'03_Assumptions_BOM'!B11/1000000 | F11: ='02_Assumptions_GPU'!G11*'03_Assumptions_BOM'!B11/1000000 | G11: ='02_Assumptions_GPU'!H11*'03_Assumptions_BOM'!B11/1000000
A12: ='03_Assumptions_BOM'!A12 | B12: ='03_Assumptions_BOM'!B12 | C12: ='02_Assumptions_GPU'!D12*'03_Assumptions_BOM'!B12/1000000 | D12: ='02_Assumptions_GPU'!E12*'03_Assumptions_BOM'!B12/1000000 | E12: ='02_Assumptions_GPU'!F12*'03_Assumptions_BOM'!B12/1000000 | F12: ='02_Assumptions_GPU'!G12*'03_Assumptions_BOM'!B12/1000000 | G12: ='02_Assumptions_GPU'!H12*'03_Assumptions_BOM'!B12/1000000
A13: ='03_Assumptions_BOM'!A13 | B13: ='03_Assumptions_BOM'!B13 | C13: ='02_Assumptions_GPU'!D13*'03_Assumptions_BOM'!B13/1000000 | D13: ='02_Assumptions_GPU'!E13*'03_Assumptions_BOM'!B13/1000000 | E13: ='02_Assumptions_GPU'!F13*'03_Assumptions_BOM'!B13/1000000 | F13: ='02_Assumptions_GPU'!G13*'03_Assumptions_BOM'!B13/1000000 | G13: ='02_Assumptions_GPU'!H13*'03_Assumptions_BOM'!B13/1000000
A14: ='03_Assumptions_BOM'!A14 | B14: ='03_Assumptions_BOM'!B14 | C14: ='02_Assumptions_GPU'!D14*'03_Assumptions_BOM'!B14/1000000 | D14: ='02_Assumptions_GPU'!E14*'03_Assumptions_BOM'!B14/1000000 | E14: ='02_Assumptions_GPU'!F14*'03_Assumptions_BOM'!B14/1000000 | F14: ='02_Assumptions_GPU'!G14*'03_Assumptions_BOM'!B14/1000000 | G14: ='02_Assumptions_GPU'!H14*'03_Assumptions_BOM'!B14/1000000
A15: ='03_Assumptions_BOM'!A15 | B15: ='03_Assumptions_BOM'!B15 | C15: ='02_Assumptions_GPU'!D15*'03_Assumptions_BOM'!B15/1000000 | D15: ='02_Assumptions_GPU'!E15*'03_Assumptions_BOM'!B15/1000000 | E15: ='02_Assumptions_GPU'!F15*'03_Assumptions_BOM'!B15/1000000 | F15: ='02_Assumptions_GPU'!G15*'03_Assumptions_BOM'!B15/1000000 | G15: ='02_Assumptions_GPU'!H15*'03_Assumptions_BOM'!B15/1000000
A16: ='03_Assumptions_BOM'!A16 | B16: ='03_Assumptions_BOM'!B16 | C16: ='02_Assumptions_GPU'!D16*'03_Assumptions_BOM'!B16/1000000 | D16: ='02_Assumptions_GPU'!E16*'03_Assumptions_BOM'!B16/1000000 | E16: ='02_Assumptions_GPU'!F16*'03_Assumptions_BOM'!B16/1000000 | F16: ='02_Assumptions_GPU'!G16*'03_Assumptions_BOM'!B16/1000000 | G16: ='02_Assumptions_GPU'!H16*'03_Assumptions_BOM'!B16/1000000
... A18: ='03_Assumptions_BOM'!A18 | B18: ='03_Assumptions_BOM'!B18 | C18: ='02_Assumptions_GPU'!D18*'03_Assumptions_BOM'!B18/1000000 | D18: ='02_Assumptions_GPU'!E18*'03_Assumptions_BOM'!B18/1000000 | E18: ='02_Assumptions_GPU'!F18*'03_Assumptions_BOM'!B18/1000000 | F18: ='02_Assumptions_GPU'!G18*'03_Assumptions_BOM'!B18/1000000 | G18: ='02_Assumptions_GPU'!H18*'03_Assumptions_BOM'!B18/1000000
A19: AIDC合计 MLCC需求 | C19: =SUM(C5:C18) | D19: =SUM(D5:D18) | E19: =SUM(E5:E18) | F19: =SUM(F5:F18) | G19: =SUM(G5:G18)
A20: 非AIDC需求（消费/工业/车/通讯/传统服务器） | C20: 70 | D20: 75 | E20: 80 | F20: 85 | G20: 90
A21: 高端MLCC总需求 | C21: =C19+C20 | D21: =D19+D20 | E21: =E19+E20 | F21: =F19+F20 | G21: =G19+G20

Sheet 06_Demand_Inductor
A1: 功率电感需求矩阵（按平台×年，单位：亿颗）
A2: 需求 = 平台出货量(千) × 单机电感用量(颗) ÷ 100,000 = 亿颗
A4: 平台 | B4: 单机电感用量(颗) | C4: 2024 | D4: 2025 | E4: 2026 | F4: 2027 | G4: 2028
A5: ='03_Assumptions_BOM'!A5 | B5: ='03_Assumptions_BOM'!D5 | C5: ='02_Assumptions_GPU'!D5*'03_Assumptions_BOM'!D5/100000 | D5: ='02_Assumptions_GPU'!E5*'03_Assumptions_BOM'!D5/100000 | E5: ='02_Assumptions_GPU'!F5*'03_Assumptions_BOM'!D5/100000 | F5: ='02_Assumptions_GPU'!G5*'03_Assumptions_BOM'!D5/100000 | G5: ='02_Assumptions_GPU'!H5*'03_Assumptions_BOM'!D5/100000
A6: ='03_Assumptions_BOM'!A6 | B6: ='03_Assumptions_BOM'!D6 | C6: ='02_Assumptions_GPU'!D6*'03_Assumptions_BOM'!D6/100000 | D6: ='02_Assumptions_GPU'!E6*'03_Assumptions_BOM'!D6/100000 | E6: ='02_Assumptions_GPU'!F6*'03_Assumptions_BOM'!D6/100000 | F6: ='02_Assumptions_GPU'!G6*'03_Assumptions_BOM'!D6/100000 | G6: ='02_Assumptions_GPU'!H6*'03_Assumptions_BOM'!D6/100000
A7: ='03_Assumptions_BOM'!A7 | B7: ='03_Assumptions_BOM'!D7 | C7: ='02_Assumptions_GPU'!D7*'03_Assumptions_BOM'!D7/100000 | D7: ='02_Assumptions_GPU'!E7*'03_Assumptions_BOM'!D7/100000 | E7: ='02_Assumptions_GPU'!F7*'03_Assumptions_BOM'!D7/100000 | F7: ='02_Assumptions_GPU'!G7*'03_Assumptions_BOM'!D7/100000 | G7: ='02_Assumptions_GPU'!H7*'03_Assumptions_BOM'!D7/100000
A8: ='03_Assumptions_BOM'!A8 | B8: ='03_Assumptions_BOM'!D8 | C8: ='02_Assumptions_GPU'!D8*'03_Assumptions_BOM'!D8/100000 | D8: ='02_Assumptions_GPU'!E8*'03_Assumptions_BOM'!D8/100000 | E8: ='02_Assumptions_GPU'!F8*'03_Assumptions_BOM'!D8/100000 | F8: ='02_Assumptions_GPU'!G8*'03_Assumptions_BOM'!D8/100000 | G8: ='02_Assumptions_GPU'!H8*'03_Assumptions_BOM'!D8/100000
A9: ='03_Assumptions_BOM'!A9 | B9: ='03_Assumptions_BOM'!D9 | C9: ='02_Assumptions_GPU'!D9*'03_Assumptions_BOM'!D9/100000 | D9: ='02_Assumptions_GPU'!E9*'03_Assumptions_BOM'!D9/100000 | E9: ='02_Assumptions_GPU'!F9*'03_Assumptions_BOM'!D9/100000 | F9: ='02_Assumptions_GPU'!G9*'03_Assumptions_BOM'!D9/100000 | G9: ='02_Assumptions_GPU'!H9*'03_Assumptions_BOM'!D9/100000
A10: ='03_Assumptions_BOM'!A10 | B10: ='03_Assumptions_BOM'!D10 | C10: ='02_Assumptions_GPU'!D10*'03_Assumptions_BOM'!D10/100000 | D10: ='02_Assumptions_GPU'!E10*'03_Assumptions_BOM'!D10/100000 | E10: ='02_Assumptions_GPU'!F10*'03_Assumptions_BOM'!D10/100000 | F10: ='02_Assumptions_GPU'!G10*'03_Assumptions_BOM'!D10/100000 | G10: ='02_Assumptions_GPU'!H10*'03_Assumptions_BOM'!D10/100000
A11: ='03_Assumptions_BOM'!A11 | B11: ='03_Assumptions_BOM'!D11 | C11: ='02_Assumptions_GPU'!D11*'03_Assumptions_BOM'!D11/100000 | D11: ='02_Assumptions_GPU'!E11*'03_Assumptions_BOM'!D11/100000 | E11: ='02_Assumptions_GPU'!F11*'03_Assumptions_BOM'!D11/100000 | F11: ='02_Assumptions_GPU'!G11*'03_Assumptions_BOM'!D11/100000 | G11: ='02_Assumptions_GPU'!H11*'03_Assumptions_BOM'!D11/100000
A12: ='03_Assumptions_BOM'!A12 | B12: ='03_Assumptions_BOM'!D12 | C12: ='02_Assumptions_GPU'!D12*'03_Assumptions_BOM'!D12/100000 | D12: ='02_Assumptions_GPU'!E12*'03_Assumptions_BOM'!D12/100000 | E12: ='02_Assumptions_GPU'!F12*'03_Assumptions_BOM'!D12/100000 | F12: ='02_Assumptions_GPU'!G12*'03_Assumptions_BOM'!D12/100000 | G12: ='02_Assumptions_GPU'!H12*'03_Assumptions_BOM'!D12/100000
A13: ='03_Assumptions_BOM'!A13 | B13: ='03_Assumptions_BOM'!D13 | C13: ='02_Assumptions_GPU'!D13*'03_Assumptions_BOM'!D13/100000 | D13: ='02_Assumptions_GPU'!E13*'03_Assumptions_BOM'!D13/100000 | E13: ='02_Assumptions_GPU'!F13*'03_Assumptions_BOM'!D13/100000 | F13: ='02_Assumptions_GPU'!G13*'03_Assumptions_BOM'!D13/100000 | G13: ='02_Assumptions_GPU'!H13*'03_Assumptions_BOM'!D13/100000
A14: ='03_Assumptions_BOM'!A14 | B14: ='03_Assumptions_BOM'!D14 | C14: ='02_Assumptions_GPU'!D14*'03_Assumptions_BOM'!D14/100000 | D14: ='02_Assumptions_GPU'!E14*'03_Assumptions_BOM'!D14/100000 | E14: ='02_Assumptions_GPU'!F14*'03_Assumptions_BOM'!D14/100000 | F14: ='02_Assumptions_GPU'!G14*'03_Assumptions_BOM'!D14/100000 | G14: ='02_Assumptions_GPU'!H14*'03_Assumptions_BOM'!D14/100000
A15: ='03_Assumptions_BOM'!A15 | B15: ='03_Assumptions_BOM'!D15 | C15: ='02_Assumptions_GPU'!D15*'03_Assumptions_BOM'!D15/100000 | D15: ='02_Assumptions_GPU'!E15*'03_Assumptions_BOM'!D15/100000 | E15: ='02_Assumptions_GPU'!F15*'03_Assumptions_BOM'!D15/100000 | F15: ='02_Assumptions_GPU'!G15*'03_Assumptions_BOM'!D15/100000 | G15: ='02_Assumptions_GPU'!H15*'03_Assumptions_BOM'!D15/100000
A16: ='03_Assumptions_BOM'!A16 | B16: ='03_Assumptions_BOM'!D16 | C16: ='02_Assumptions_GPU'!D16*'03_Assumptions_BOM'!D16/100000 | D16: ='02_Assumptions_GPU'!E16*'03_Assumptions_BOM'!D16/100000 | E16: ='02_Assumptions_GPU'!F16*'03_Assumptions_BOM'!D16/100000 | F16: ='02_Assumptions_GPU'!G16*'03_Assumptions_BOM'!D16/100000 | G16: ='02_Assumptions_GPU'!H16*'03_Assumptions_BOM'!D16/100000
... A18: ='03_Assumptions_BOM'!A18 | B18: ='03_Assumptions_BOM'!D18 | C18: ='02_Assumptions_GPU'!D18*'03_Assumptions_BOM'!D18/100000 | D18: ='02_Assumptions_GPU'!E18*'03_Assumptions_BOM'!D18/100000 | E18: ='02_Assumptions_GPU'!F18*'03_Assumptions_BOM'!D18/100000 | F18: ='02_Assumptions_GPU'!G18*'03_Assumptions_BOM'!D18/100000 | G18: ='02_Assumptions_GPU'!H18*'03_Assumptions_BOM'!D18/100000
A19: AIDC合计 电感需求 | C19: =SUM(C5:C18) | D19: =SUM(D5:D18) | E19: =SUM(E5:E18) | F19: =SUM(F5:F18) | G19: =SUM(G5:G18)
A20: 非AIDC电感需求 | C20: 22 | D20: 24 | E20: 26 | F20: 28 | G20: 30
A21: 高端电感总需求 | C21: =C19+C20 | D21: =D19+D20 | E21: =E19+E20 | F21: =F19+F20 | G21: =G19+G20

Sheet 07_Demand_FilmCap
A1: 薄膜电容需求矩阵（按平台×年，单位：百万颗）
A2: 需求 = 平台出货量(千) × 单机薄膜电容(颗) ÷ 1,000 = 百万颗
A4: 平台 | B4: 单机薄膜用量(颗) | C4: 2024 | D4: 2025 | E4: 2026 | F4: 2027 | G4: 2028
A5: ='03_Assumptions_BOM'!A5 | B5: ='03_Assumptions_BOM'!E5 | C5: ='02_Assumptions_GPU'!D5*'03_Assumptions_BOM'!E5/1000 | D5: ='02_Assumptions_GPU'!E5*'03_Assumptions_BOM'!E5/1000 | E5: ='02_Assumptions_GPU'!F5*'03_Assumptions_BOM'!E5/1000 | F5: ='02_Assumptions_GPU'!G5*'03_Assumptions_BOM'!E5/1000 | G5: ='02_Assumptions_GPU'!H5*'03_Assumptions_BOM'!E5/1000
A6: ='03_Assumptions_BOM'!A6 | B6: ='03_Assumptions_BOM'!E6 | C6: ='02_Assumptions_GPU'!D6*'03_Assumptions_BOM'!E6/1000 | D6: ='02_Assumptions_GPU'!E6*'03_Assumptions_BOM'!E6/1000 | E6: ='02_Assumptions_GPU'!F6*'03_Assumptions_BOM'!E6/1000 | F6: ='02_Assumptions_GPU'!G6*'03_Assumptions_BOM'!E6/1000 | G6: ='02_Assumptions_GPU'!H6*'03_Assumptions_BOM'!E6/1000
A7: ='03_Assumptions_BOM'!A7 | B7: ='03_Assumptions_BOM'!E7 | C7: ='02_Assumptions_GPU'!D7*'03_Assumptions_BOM'!E7/1000 | D7: ='02_Assumptions_GPU'!E7*'03_Assumptions_BOM'!E7/1000 | E7: ='02_Assumptions_GPU'!F7*'03_Assumptions_BOM'!E7/1000 | F7: ='02_Assumptions_GPU'!G7*'03_Assumptions_BOM'!E7/1000 | G7: ='02_Assumptions_GPU'!H7*'03_Assumptions_BOM'!E7/1000
A8: ='03_Assumptions_BOM'!A8 | B8: ='03_Assumptions_BOM'!E8 | C8: ='02_Assumptions_GPU'!D8*'03_Assumptions_BOM'!E8/1000 | D8: ='02_Assumptions_GPU'!E8*'03_Assumptions_BOM'!E8/1000 | E8: ='02_Assumptions_GPU'!F8*'03_Assumptions_BOM'!E8/1000 | F8: ='02_Assumptions_GPU'!G8*'03_Assumptions_BOM'!E8/1000 | G8: ='02_Assumptions_GPU'!H8*'03_Assumptions_BOM'!E8/1000
A9: ='03_Assumptions_BOM'!A9 | B9: ='03_Assumptions_BOM'!E9 | C9: ='02_Assumptions_GPU'!D9*'03_Assumptions_BOM'!E9/1000 | D9: ='02_Assumptions_GPU'!E9*'03_Assumptions_BOM'!E9/1000 | E9: ='02_Assumptions_GPU'!F9*'03_Assumptions_BOM'!E9/1000 | F9: ='02_Assumptions_GPU'!G9*'03_Assumptions_BOM'!E9/1000 | G9: ='02_Assumptions_GPU'!H9*'03_Assumptions_BOM'!E9/1000
A10: ='03_Assumptions_BOM'!A10 | B10: ='03_Assumptions_BOM'!E10 | C10: ='02_Assumptions_GPU'!D10*'03_Assumptions_BOM'!E10/1000 | D10: ='02_Assumptions_GPU'!E10*'03_Assumptions_BOM'!E10/1000 | E10: ='02_Assumptions_GPU'!F10*'03_Assumptions_BOM'!E10/1000 | F10: ='02_Assumptions_GPU'!G10*'03_Assumptions_BOM'!E10/1000 | G10: ='02_Assumptions_GPU'!H10*'03_Assumptions_BOM'!E10/1000
A11: ='03_Assumptions_BOM'!A11 | B11: ='03_Assumptions_BOM'!E11 | C11: ='02_Assumptions_GPU'!D11*'03_Assumptions_BOM'!E11/1000 | D11: ='02_Assumptions_GPU'!E11*'03_Assumptions_BOM'!E11/1000 | E11: ='02_Assumptions_GPU'!F11*'03_Assumptions_BOM'!E11/1000 | F11: ='02_Assumptions_GPU'!G11*'03_Assumptions_BOM'!E11/1000 | G11: ='02_Assumptions_GPU'!H11*'03_Assumptions_BOM'!E11/1000
A12: ='03_Assumptions_BOM'!A12 | B12: ='03_Assumptions_BOM'!E12 | C12: ='02_Assumptions_GPU'!D12*'03_Assumptions_BOM'!E12/1000 | D12: ='02_Assumptions_GPU'!E12*'03_Assumptions_BOM'!E12/1000 | E12: ='02_Assumptions_GPU'!F12*'03_Assumptions_BOM'!E12/1000 | F12: ='02_Assumptions_GPU'!G12*'03_Assumptions_BOM'!E12/1000 | G12: ='02_Assumptions_GPU'!H12*'03_Assumptions_BOM'!E12/1000
A13: ='03_Assumptions_BOM'!A13 | B13: ='03_Assumptions_BOM'!E13 | C13: ='02_Assumptions_GPU'!D13*'03_Assumptions_BOM'!E13/1000 | D13: ='02_Assumptions_GPU'!E13*'03_Assumptions_BOM'!E13/1000 | E13: ='02_Assumptions_GPU'!F13*'03_Assumptions_BOM'!E13/1000 | F13: ='02_Assumptions_GPU'!G13*'03_Assumptions_BOM'!E13/1000 | G13: ='02_Assumptions_GPU'!H13*'03_Assumptions_BOM'!E13/1000
A14: ='03_Assumptions_BOM'!A14 | B14: ='03_Assumptions_BOM'!E14 | C14: ='02_Assumptions_GPU'!D14*'03_Assumptions_BOM'!E14/1000 | D14: ='02_Assumptions_GPU'!E14*'03_Assumptions_BOM'!E14/1000 | E14: ='02_Assumptions_GPU'!F14*'03_Assumptions_BOM'!E14/1000 | F14: ='02_Assumptions_GPU'!G14*'03_Assumptions_BOM'!E14/1000 | G14: ='02_Assumptions_GPU'!H14*'03_Assumptions_BOM'!E14/1000
A15: ='03_Assumptions_BOM'!A15 | B15: ='03_Assumptions_BOM'!E15 | C15: ='02_Assumptions_GPU'!D15*'03_Assumptions_BOM'!E15/1000 | D15: ='02_Assumptions_GPU'!E15*'03_Assumptions_BOM'!E15/1000 | E15: ='02_Assumptions_GPU'!F15*'03_Assumptions_BOM'!E15/1000 | F15: ='02_Assumptions_GPU'!G15*'03_Assumptions_BOM'!E15/1000 | G15: ='02_Assumptions_GPU'!H15*'03_Assumptions_BOM'!E15/1000
A16: ='03_Assumptions_BOM'!A16 | B16: ='03_Assumptions_BOM'!E16 | C16: ='02_Assumptions_GPU'!D16*'03_Assumptions_BOM'!E16/1000 | D16: ='02_Assumptions_GPU'!E16*'03_Assumptions_BOM'!E16/1000 | E16: ='02_Assumptions_GPU'!F16*'03_Assumptions_BOM'!E16/1000 | F16: ='02_Assumptions_GPU'!G16*'03_Assumptions_BOM'!E16/1000 | G16: ='02_Assumptions_GPU'!H16*'03_Assumptions_BOM'!E16/1000
... A18: ='03_Assumptions_BOM'!A18 | B18: ='03_Assumptions_BOM'!E18 | C18: ='02_Assumptions_GPU'!D18*'03_Assumptions_BOM'!E18/1000 | D18: ='02_Assumptions_GPU'!E18*'03_Assumptions_BOM'!E18/1000 | E18: ='02_Assumptions_GPU'!F18*'03_Assumptions_BOM'!E18/1000 | F18: ='02_Assumptions_GPU'!G18*'03_Assumptions_BOM'!E18/1000 | G18: ='02_Assumptions_GPU'!H18*'03_Assumptions_BOM'!E18/1000
A19: AIDC合计 薄膜需求 | C19: =SUM(C5:C18) | D19: =SUM(D5:D18) | E19: =SUM(E5:E18) | F19: =SUM(F5:F18) | G19: =SUM(G5:G18)
A20: HVDC基础设施+UPS+其他薄膜需求 | C20: 180 | D20: 190 | E20: 210 | F20: 230 | G20: 260
A21: HVDC薄膜总需求 | C21: =C19+C20 | D21: =D19+D20 | E21: =E19+E20 | F21: =F19+F20 | G21: =G19+G20

Sheet 08_Demand_Other
A1: 其他被动元件需求：钽聚合物 / 铝电解 / 超级电容 / 片式电阻
A2: 单位：钽=百万颗，铝电解=百万颗，超容=千颗，电阻=十亿颗
A4: [A] 钽聚合物电容（百万颗）
A5: 平台 | B5: 单机用量 | C5: 2024 | D5: 2025 | E5: 2026 | F5: 2027 | G5: 2028
A6: ='03_Assumptions_BOM'!A5 | B6: ='03_Assumptions_BOM'!F5 | C6: ='02_Assumptions_GPU'!D5*'03_Assumptions_BOM'!F5/1000 | D6: ='02_Assumptions_GPU'!E5*'03_Assumptions_BOM'!F5/1000 | E6: ='02_Assumptions_GPU'!F5*'03_Assumptions_BOM'!F5/1000 | F6: ='02_Assumptions_GPU'!G5*'03_Assumptions_BOM'!F5/1000 | G6: ='02_Assumptions_GPU'!H5*'03_Assumptions_BOM'!F5/1000
A7: ='03_Assumptions_BOM'!A6 | B7: ='03_Assumptions_BOM'!F6 | C7: ='02_Assumptions_GPU'!D6*'03_Assumptions_BOM'!F6/1000 | D7: ='02_Assumptions_GPU'!E6*'03_Assumptions_BOM'!F6/1000 | E7: ='02_Assumptions_GPU'!F6*'03_Assumptions_BOM'!F6/1000 | F7: ='02_Assumptions_GPU'!G6*'03_Assumptions_BOM'!F6/1000 | G7: ='02_Assumptions_GPU'!H6*'03_Assumptions_BOM'!F6/1000
A8: ='03_Assumptions_BOM'!A7 | B8: ='03_Assumptions_BOM'!F7 | C8: ='02_Assumptions_GPU'!D7*'03_Assumptions_BOM'!F7/1000 | D8: ='02_Assumptions_GPU'!E7*'03_Assumptions_BOM'!F7/1000 | E8: ='02_Assumptions_GPU'!F7*'03_Assumptions_BOM'!F7/1000 | F8: ='02_Assumptions_GPU'!G7*'03_Assumptions_BOM'!F7/1000 | G8: ='02_Assumptions_GPU'!H7*'03_Assumptions_BOM'!F7/1000
A9: ='03_Assumptions_BOM'!A8 | B9: ='03_Assumptions_BOM'!F8 | C9: ='02_Assumptions_GPU'!D8*'03_Assumptions_BOM'!F8/1000 | D9: ='02_Assumptions_GPU'!E8*'03_Assumptions_BOM'!F8/1000 | E9: ='02_Assumptions_GPU'!F8*'03_Assumptions_BOM'!F8/1000 | F9: ='02_Assumptions_GPU'!G8*'03_Assumptions_BOM'!F8/1000 | G9: ='02_Assumptions_GPU'!H8*'03_Assumptions_BOM'!F8/1000
A10: ='03_Assumptions_BOM'!A9 | B10: ='03_Assumptions_BOM'!F9 | C10: ='02_Assumptions_GPU'!D9*'03_Assumptions_BOM'!F9/1000 | D10: ='02_Assumptions_GPU'!E9*'03_Assumptions_BOM'!F9/1000 | E10: ='02_Assumptions_GPU'!F9*'03_Assumptions_BOM'!F9/1000 | F10: ='02_Assumptions_GPU'!G9*'03_Assumptions_BOM'!F9/1000 | G10: ='02_Assumptions_GPU'!H9*'03_Assumptions_BOM'!F9/1000
A11: ='03_Assumptions_BOM'!A10 | B11: ='03_Assumptions_BOM'!F10 | C11: ='02_Assumptions_GPU'!D10*'03_Assumptions_BOM'!F10/1000 | D11: ='02_Assumptions_GPU'!E10*'03_Assumptions_BOM'!F10/1000 | E11: ='02_Assumptions_GPU'!F10*'03_Assumptions_BOM'!F10/1000 | F11: ='02_Assumptions_GPU'!G10*'03_Assumptions_BOM'!F10/1000 | G11: ='02_Assumptions_GPU'!H10*'03_Assumptions_BOM'!F10/1000
A12: ='03_Assumptions_BOM'!A11 | B12: ='03_Assumptions_BOM'!F11 | C12: ='02_Assumptions_GPU'!D11*'03_Assumptions_BOM'!F11/1000 | D12: ='02_Assumptions_GPU'!E11*'03_Assumptions_BOM'!F11/1000 | E12: ='02_Assumptions_GPU'!F11*'03_Assumptions_BOM'!F11/1000 | F12: ='02_Assumptions_GPU'!G11*'03_Assumptions_BOM'!F11/1000 | G12: ='02_Assumptions_GPU'!H11*'03_Assumptions_BOM'!F11/1000
A13: ='03_Assumptions_BOM'!A12 | B13: ='03_Assumptions_BOM'!F12 | C13: ='02_Assumptions_GPU'!D12*'03_Assumptions_BOM'!F12/1000 | D13: ='02_Assumptions_GPU'!E12*'03_Assumptions_BOM'!F12/1000 | E13: ='02_Assumptions_GPU'!F12*'03_Assumptions_BOM'!F12/1000 | F13: ='02_Assumptions_GPU'!G12*'03_Assumptions_BOM'!F12/1000 | G13: ='02_Assumptions_GPU'!H12*'03_Assumptions_BOM'!F12/1000
A14: ='03_Assumptions_BOM'!A13 | B14: ='03_Assumptions_BOM'!F13 | C14: ='02_Assumptions_GPU'!D13*'03_Assumptions_BOM'!F13/1000 | D14: ='02_Assumptions_GPU'!E13*'03_Assumptions_BOM'!F13/1000 | E14: ='02_Assumptions_GPU'!F13*'03_Assumptions_BOM'!F13/1000 | F14: ='02_Assumptions_GPU'!G13*'03_Assumptions_BOM'!F13/1000 | G14: ='02_Assumptions_GPU'!H13*'03_Assumptions_BOM'!F13/1000
A15: ='03_Assumptions_BOM'!A14 | B15: ='03_Assumptions_BOM'!F14 | C15: ='02_Assumptions_GPU'!D14*'03_Assumptions_BOM'!F14/1000 | D15: ='02_Assumptions_GPU'!E14*'03_Assumptions_BOM'!F14/1000 | E15: ='02_Assumptions_GPU'!F14*'03_Assumptions_BOM'!F14/1000 | F15: ='02_Assumptions_GPU'!G14*'03_Assumptions_BOM'!F14/1000 | G15: ='02_Assumptions_GPU'!H14*'03_Assumptions_BOM'!F14/1000
A16: ='03_Assumptions_BOM'!A15 | B16: ='03_Assumptions_BOM'!F15 | C16: ='02_Assumptions_GPU'!D15*'03_Assumptions_BOM'!F15/1000 | D16: ='02_Assumptions_GPU'!E15*'03_Assumptions_BOM'!F15/1000 | E16: ='02_Assumptions_GPU'!F15*'03_Assumptions_BOM'!F15/1000 | F16: ='02_Assumptions_GPU'!G15*'03_Assumptions_BOM'!F15/1000 | G16: ='02_Assumptions_GPU'!H15*'03_Assumptions_BOM'!F15/1000
A17: ='03_Assumptions_BOM'!A16 | B17: ='03_Assumptions_BOM'!F16 | C17: ='02_Assumptions_GPU'!D16*'03_Assumptions_BOM'!F16/1000 | D17: ='02_Assumptions_GPU'!E16*'03_Assumptions_BOM'!F16/1000 | E17: ='02_Assumptions_GPU'!F16*'03_Assumptions_BOM'!F16/1000 | F17: ='02_Assumptions_GPU'!G16*'03_Assumptions_BOM'!F16/1000 | G17: ='02_Assumptions_GPU'!H16*'03_Assumptions_BOM'!F16/1000
... A19: ='03_Assumptions_BOM'!A18 | B19: ='03_Assumptions_BOM'!F18 | C19: ='02_Assumptions_GPU'!D18*'03_Assumptions_BOM'!F18/1000 | D19: ='02_Assumptions_GPU'!E18*'03_Assumptions_BOM'!F18/1000 | E19: ='02_Assumptions_GPU'!F18*'03_Assumptions_BOM'!F18/1000 | F19: ='02_Assumptions_GPU'!G18*'03_Assumptions_BOM'!F18/1000 | G19: ='02_Assumptions_GPU'!H18*'03_Assumptions_BOM'!F18/1000
A20: AIDC小计 | C20: =SUM(C6:C19) | D20: =SUM(D6:D19) | E20: =SUM(E6:E19) | F20: =SUM(F6:F19) | G20: =SUM(G6:G19)
A22: [B] 铝电解电容（百万颗）
A23: 平台 | B23: 单机用量 | C23: 2024 | D23: 2025 | E23: 2026 | F23: 2027 | G23: 2028
A24: ='03_Assumptions_BOM'!A5 | B24: ='03_Assumptions_BOM'!G5 | C24: ='02_Assumptions_GPU'!D5*'03_Assumptions_BOM'!G5/1000 | D24: ='02_Assumptions_GPU'!E5*'03_Assumptions_BOM'!G5/1000 | E24: ='02_Assumptions_GPU'!F5*'03_Assumptions_BOM'!G5/1000 | F24: ='02_Assumptions_GPU'!G5*'03_Assumptions_BOM'!G5/1000 | G24: ='02_Assumptions_GPU'!H5*'03_Assumptions_BOM'!G5/1000
A25: ='03_Assumptions_BOM'!A6 | B25: ='03_Assumptions_BOM'!G6 | C25: ='02_Assumptions_GPU'!D6*'03_Assumptions_BOM'!G6/1000 | D25: ='02_Assumptions_GPU'!E6*'03_Assumptions_BOM'!G6/1000 | E25: ='02_Assumptions_GPU'!F6*'03_Assumptions_BOM'!G6/1000 | F25: ='02_Assumptions_GPU'!G6*'03_Assumptions_BOM'!G6/1000 | G25: ='02_Assumptions_GPU'!H6*'03_Assumptions_BOM'!G6/1000
A26: ='03_Assumptions_BOM'!A7 | B26: ='03_Assumptions_BOM'!G7 | C26: ='02_Assumptions_GPU'!D7*'03_Assumptions_BOM'!G7/1000 | D26: ='02_Assumptions_GPU'!E7*'03_Assumptions_BOM'!G7/1000 | E26: ='02_Assumptions_GPU'!F7*'03_Assumptions_BOM'!G7/1000 | F26: ='02_Assumptions_GPU'!G7*'03_Assumptions_BOM'!G7/1000 | G26: ='02_Assumptions_GPU'!H7*'03_Assumptions_BOM'!G7/1000
A27: ='03_Assumptions_BOM'!A8 | B27: ='03_Assumptions_BOM'!G8 | C27: ='02_Assumptions_GPU'!D8*'03_Assumptions_BOM'!G8/1000 | D27: ='02_Assumptions_GPU'!E8*'03_Assumptions_BOM'!G8/1000 | E27: ='02_Assumptions_GPU'!F8*'03_Assumptions_BOM'!G8/1000 | F27: ='02_Assumptions_GPU'!G8*'03_Assumptions_BOM'!G8/1000 | G27: ='02_Assumptions_GPU'!H8*'03_Assumptions_BOM'!G8/1000
A28: ='03_Assumptions_BOM'!A9 | B28: ='03_Assumptions_BOM'!G9 | C28: ='02_Assumptions_GPU'!D9*'03_Assumptions_BOM'!G9/1000 | D28: ='02_Assumptions_GPU'!E9*'03_Assumptions_BOM'!G9/1000 | E28: ='02_Assumptions_GPU'!F9*'03_Assumptions_BOM'!G9/1000 | F28: ='02_Assumptions_GPU'!G9*'03_Assumptions_BOM'!G9/1000 | G28: ='02_Assumptions_GPU'!H9*'03_Assumptions_BOM'!G9/1000
A29: ='03_Assumptions_BOM'!A10 | B29: ='03_Assumptions_BOM'!G10 | C29: ='02_Assumptions_GPU'!D10*'03_Assumptions_BOM'!G10/1000 | D29: ='02_Assumptions_GPU'!E10*'03_Assumptions_BOM'!G10/1000 | E29: ='02_Assumptions_GPU'!F10*'03_Assumptions_BOM'!G10/1000 | F29: ='02_Assumptions_GPU'!G10*'03_Assumptions_BOM'!G10/1000 | G29: ='02_Assumptions_GPU'!H10*'03_Assumptions_BOM'!G10/1000
A30: ='03_Assumptions_BOM'!A11 | B30: ='03_Assumptions_BOM'!G11 | C30: ='02_Assumptions_GPU'!D11*'03_Assumptions_BOM'!G11/1000 | D30: ='02_Assumptions_GPU'!E11*'03_Assumptions_BOM'!G11/1000 | E30: ='02_Assumptions_GPU'!F11*'03_Assumptions_BOM'!G11/1000 | F30: ='02_Assumptions_GPU'!G11*'03_Assumptions_BOM'!G11/1000 | G30: ='02_Assumptions_GPU'!H11*'03_Assumptions_BOM'!G11/1000
A31: ='03_Assumptions_BOM'!A12 | B31: ='03_Assumptions_BOM'!G12 | C31: ='02_Assumptions_GPU'!D12*'03_Assumptions_BOM'!G12/1000 | D31: ='02_Assumptions_GPU'!E12*'03_Assumptions_BOM'!G12/1000 | E31: ='02_Assumptions_GPU'!F12*'03_Assumptions_BOM'!G12/1000 | F31: ='02_Assumptions_GPU'!G12*'03_Assumptions_BOM'!G12/1000 | G31: ='02_Assumptions_GPU'!H12*'03_Assumptions_BOM'!G12/1000
A32: ='03_Assumptions_BOM'!A13 | B32: ='03_Assumptions_BOM'!G13 | C32: ='02_Assumptions_GPU'!D13*'03_Assumptions_BOM'!G13/1000 | D32: ='02_Assumptions_GPU'!E13*'03_Assumptions_BOM'!G13/1000 | E32: ='02_Assumptions_GPU'!F13*'03_Assumptions_BOM'!G13/1000 | F32: ='02_Assumptions_GPU'!G13*'03_Assumptions_BOM'!G13/1000 | G32: ='02_Assumptions_GPU'!H13*'03_Assumptions_BOM'!G13/1000
A33: ='03_Assumptions_BOM'!A14 | B33: ='03_Assumptions_BOM'!G14 | C33: ='02_Assumptions_GPU'!D14*'03_Assumptions_BOM'!G14/1000 | D33: ='02_Assumptions_GPU'!E14*'03_Assumptions_BOM'!G14/1000 | E33: ='02_Assumptions_GPU'!F14*'03_Assumptions_BOM'!G14/1000 | F33: ='02_Assumptions_GPU'!G14*'03_Assumptions_BOM'!G14/1000 | G33: ='02_Assumptions_GPU'!H14*'03_Assumptions_BOM'!G14/1000
A34: ='03_Assumptions_BOM'!A15 | B34: ='03_Assumptions_BOM'!G15 | C34: ='02_Assumptions_GPU'!D15*'03_Assumptions_BOM'!G15/1000 | D34: ='02_Assumptions_GPU'!E15*'03_Assumptions_BOM'!G15/1000 | E34: ='02_Assumptions_GPU'!F15*'03_Assumptions_BOM'!G15/1000 | F34: ='02_Assumptions_GPU'!G15*'03_Assumptions_BOM'!G15/1000 | G34: ='02_Assumptions_GPU'!H15*'03_Assumptions_BOM'!G15/1000
A35: ='03_Assumptions_BOM'!A16 | B35: ='03_Assumptions_BOM'!G16 | C35: ='02_Assumptions_GPU'!D16*'03_Assumptions_BOM'!G16/1000 | D35: ='02_Assumptions_GPU'!E16*'03_Assumptions_BOM'!G16/1000 | E35: ='02_Assumptions_GPU'!F16*'03_Assumptions_BOM'!G16/1000 | F35: ='02_Assumptions_GPU'!G16*'03_Assumptions_BOM'!G16/1000 | G35: ='02_Assumptions_GPU'!H16*'03_Assumptions_BOM'!G16/1000
... A37: ='03_Assumptions_BOM'!A18 | B37: ='03_Assumptions_BOM'!G18 | C37: ='02_Assumptions_GPU'!D18*'03_Assumptions_BOM'!G18/1000 | D37: ='02_Assumptions_GPU'!E18*'03_Assumptions_BOM'!G18/1000 | E37: ='02_Assumptions_GPU'!F18*'03_Assumptions_BOM'!G18/1000 | F37: ='02_Assumptions_GPU'!G18*'03_Assumptions_BOM'!G18/1000 | G37: ='02_Assumptions_GPU'!H18*'03_Assumptions_BOM'!G18/1000
A38: AIDC小计 | C38: =SUM(C24:C37) | D38: =SUM(D24:D37) | E38: =SUM(E24:E37) | F38: =SUM(F24:F37) | G38: =SUM(G24:G37)
A40: [C] 超级电容（千颗）
A41: 平台 | B41: 单机用量 | C41: 2024 | D41: 2025 | E41: 2026 | F41: 2027 | G41: 2028
A42: ='03_Assumptions_BOM'!A5 | B42: ='03_Assumptions_BOM'!H5 | C42: ='02_Assumptions_GPU'!D5*'03_Assumptions_BOM'!H5/1 | D42: ='02_Assumptions_GPU'!E5*'03_Assumptions_BOM'!H5/1 | E42: ='02_Assumptions_GPU'!F5*'03_Assumptions_BOM'!H5/1 | F42: ='02_Assumptions_GPU'!G5*'03_Assumptions_BOM'!H5/1 | G42: ='02_Assumptions_GPU'!H5*'03_Assumptions_BOM'!H5/1
A43: ='03_Assumptions_BOM'!A6 | B43: ='03_Assumptions_BOM'!H6 | C43: ='02_Assumptions_GPU'!D6*'03_Assumptions_BOM'!H6/1 | D43: ='02_Assumptions_GPU'!E6*'03_Assumptions_BOM'!H6/1 | E43: ='02_Assumptions_GPU'!F6*'03_Assumptions_BOM'!H6/1 | F43: ='02_Assumptions_GPU'!G6*'03_Assumptions_BOM'!H6/1 | G43: ='02_Assumptions_GPU'!H6*'03_Assumptions_BOM'!H6/1
A44: ='03_Assumptions_BOM'!A7 | B44: ='03_Assumptions_BOM'!H7 | C44: ='02_Assumptions_GPU'!D7*'03_Assumptions_BOM'!H7/1 | D44: ='02_Assumptions_GPU'!E7*'03_Assumptions_BOM'!H7/1 | E44: ='02_Assumptions_GPU'!F7*'03_Assumptions_BOM'!H7/1 | F44: ='02_Assumptions_GPU'!G7*'03_Assumptions_BOM'!H7/1 | G44: ='02_Assumptions_GPU'!H7*'03_Assumptions_BOM'!H7/1
A45: ='03_Assumptions_BOM'!A8 | B45: ='03_Assumptions_BOM'!H8 | C45: ='02_Assumptions_GPU'!D8*'03_Assumptions_BOM'!H8/1 | D45: ='02_Assumptions_GPU'!E8*'03_Assumptions_BOM'!H8/1 | E45: ='02_Assumptions_GPU'!F8*'03_Assumptions_BOM'!H8/1 | F45: ='02_Assumptions_GPU'!G8*'03_Assumptions_BOM'!H8/1 | G45: ='02_Assumptions_GPU'!H8*'03_Assumptions_BOM'!H8/1
...

Sheet 09_Gap_Analysis
A1: 供需缺口与价格弹性预测（核心sheet）
A3: [A] MLCC高端品类供需缺口（十亿颗）
A4: 项目 | B4: 2024 | C4: 2025 | D4: 2026 | E4: 2027 | F4: 2028 | G4: 备注
A5: 供给（高端MLCC总产能） | B5: ='04_Assumptions_Supply'!B15 | C5: ='04_Assumptions_Supply'!C15 | D5: ='04_Assumptions_Supply'!D15 | E5: ='04_Assumptions_Supply'!E15 | F5: ='04_Assumptions_Supply'!F15 | G5: 来自Sheet 04各原厂产能合计
A6: 需求（高端MLCC总需求） | B6: ='05_Demand_MLCC'!C21 | C6: ='05_Demand_MLCC'!D21 | D6: ='05_Demand_MLCC'!E21 | E6: ='05_Demand_MLCC'!F21 | F6: ='05_Demand_MLCC'!G21 | G6: AIDC + 非AIDC合计
A7: 缺口（供给-需求） | B7: =B5-B6 | C7: =C5-C6 | D7: =D5-D6 | E7: =E5-E6 | F7: =F5-F6 | G7: 负值=短缺
A8: 产能利用率(=需求/供给) | B8: =B6/B5 | C8: =C6/C5 | D8: =D6/D5 | E8: =E6/E5 | F8: =F6/F5 | G8: >100%表明实质性短缺
A9: MLCC高端均价同比涨幅（推算） | B9: — | C9: 5% | D9: 20% | E9: 12% | F9: 5% | G9: 基于历史弹性+原材料成本+扩产兑现
A11: [B] 高端AI功率电感供需缺口（亿颗）
A12: 项目 | B12: 2024 | C12: 2025 | D12: 2026 | E12: 2027 | F12: 2028 | G12: 备注
A13: 供给（高端电感产能） | B13: ='04_Assumptions_Supply'!B25 | C13: ='04_Assumptions_Supply'!C25 | D13: ='04_Assumptions_Supply'!D25 | E13: ='04_Assumptions_Supply'!E25 | F13: ='04_Assumptions_Supply'!F25
A14: 需求（高端电感总需求） | B14: ='06_Demand_Inductor'!C21 | C14: ='06_Demand_Inductor'!D21 | D14: ='06_Demand_Inductor'!E21 | E14: ='06_Demand_Inductor'!F21 | F14: ='06_Demand_Inductor'!G21
A15: 缺口 | B15: =B13-B14 | C15: =C13-C14 | D15: =D13-D14 | E15: =E13-E14 | F15: =F13-F14 | G15: 负值=短缺
A16: 产能利用率 | B16: =B14/B13 | C16: =C14/C13 | D16: =D14/D13 | E16: =E14/E13 | F16: =F14/F13
A17: 电感均价同比涨幅（推算） | B17: — | C17: 8% | D17: 15% | E17: 10% | F17: 4%
A19: [C] HVDC薄膜电容供需缺口（百万颗）
A20: 项目 | B20: 2024 | C20: 2025 | D20: 2026 | E20: 2027 | F20: 2028 | G20: 备注
A21: 供给（高端薄膜产能） | B21: ='04_Assumptions_Supply'!B36 | C21: ='04_Assumptions_Supply'!C36 | D21: ='04_Assumptions_Supply'!D36 | E21: ='04_Assumptions_Supply'!E36 | F21: ='04_Assumptions_Supply'!F36
A22: 需求（HVDC薄膜总需求） | B22: ='07_Demand_FilmCap'!C21 | C22: ='07_Demand_FilmCap'!D21 | D22: ='07_Demand_FilmCap'!E21 | E22: ='07_Demand_FilmCap'!F21 | F22: ='07_Demand_FilmCap'!G21
A23: 缺口 | B23: =B21-B22 | C23: =C21-C22 | D23: =D21-D22 | E23: =E21-E22 | F23: =F21-F22
A24: 产能利用率 | B24: =B22/B21 | C24: =C22/C21 | D24: =D22/D21 | E24: =E22/E21 | F24: =F22/F21
A25: 薄膜均价同比涨幅（推算） | B25: — | C25: 6% | D25: 12% | E25: 8% | F25: 3%
A27: [D] 综合结论
A28: MLCC：2026-2027年缺口最严重，高端料号现货溢价30-40%可持续至2027H1
A29: 电感：2026年合金粉末模压电感缺口显著，国内顺络受益最直接
A30: 薄膜：HVDC普及推动+30%/年增量，法拉电子AIDC直接受益
A31: 钽聚：GB300采用强化、Panasonic 25Q4涨15-30%已落地
A32: 铝电解：AIDC寿命要求催化向固态/混合电解升级，江海受益
A33: 电阻：钌价驱动整体涨10-15%，AI单机用量是消费的6-10倍

Sheet 10_Scenarios
A1: 三情景对比：保守 / 中性 / 乐观
A2: 各情景调整核心驱动变量，比较2026-2028年MLCC价格曲线
A4: 维度 | B4: 保守情景 | C4: 中性情景（基准） | D4: 乐观情景
A5: AI capex同比 | B5: +15% | C5: +30% | D5: +45%
A6: GB300/Rubin出货量 | B6: 基准80% | C6: 基准100% | D6: 基准120%
A7: 原厂扩产兑现 | B7: 100%（按计划） | C7: 85%（小幅延期） | D7: 70%（明显延期）
A8: 国产替代进度 | B8: 加速（高端突破） | C8: 渐进（仅中端） | D8: 停滞（高端无突破）
A9: 贵金属（Ru/Ag）涨幅 | B9: -10% | C9: +5% | D9: +20%
A11: —— 测算结果 ——
A12: 2026年MLCC高端均价同比 | B12: +10% | C12: +20% | D12: +35%
A13: 2027年MLCC高端均价同比 | B13: +3% | C13: +12% | D13: +25%
A14: 2028年MLCC高端均价同比 | B14: -5% | C14: +5% | D14: +15%
A15: 2026年MLCC缺口（十亿颗） | B15: -5 | C15: -15 | D15: -30
A16: 2027年MLCC缺口（十亿颗） | B16: +5 | C16: -8 | D16: -20
A17: 2028年MLCC缺口（十亿颗） | B17: +25 | C17: +8 | D17: -10
A19: —— 投资含义 ——
A20: 龙头2026收入弹性（Murata/SEMCO） | B20: +15% | C20: +25% | D20: +40%
A21: 龙头2026EPS弹性 | B21: +25% | C21: +50% | D21: +85%
A22: 国内龙头估值修复空间 | B22: 20% | C22: 40% | D22: 70%
A24: • 保守情景：AI capex降速 + 原厂扩产准时 + 国产突破→价格软着陆，2028年回吐部分涨幅
A25: • 中性情景：基准假设，AI高景气持续到2027，2028年随产能消化温和回落
A26: • 乐观情景：AI capex超预期 + 扩产延期 + 贵金属重新上行→价格2026-2027大涨，2028仍维持高位
A27: • 情景间分歧主要在2027-2028，2026涨价确定性极高（Murata、SEMCO已锁定执行）
A28: • 投资策略：中性情景下海外龙头PE应升至25-30倍，国内龙头35-45倍

Sheet 11_Sensitivity
A1: 敏感性分析：4个核心变量对2026年MLCC缺口的弹性
A3: [1] 2026 MLCC缺口（十亿颗）：AI capex × 原厂产能兑现
A4: AI capex \ 产能兑现 | B4: 60% | C4: 75% | D4: 85%（基准） | E4: 95% | F4: 100%
A5: +50% (乐观) | B5: -38 | C5: -28 | D5: -22 | E5: -15 | F5: -10
A6: +40% (略乐观) | B6: -32 | C6: -22 | D6: -16 | E6: -9 | F6: -4
A7: +30% (基准) | B7: -25 | C7: -16 | D7: -10 | E7: -3 | F7: 2
A8: +20% (略保守) | B8: -18 | C8: -9 | D8: -3 | E8: 4 | F8: 9
A9: +10% (保守) | B9: -12 | C9: -3 | D9: 3 | E9: 10 | F9: 15
A11: [2] 2026 MLCC高端均价同比：贵金属价格 × 国产替代进度
A12: 贵金属 \ 国产替代 | B12: 加速（高端突破） | C12: 正常 | D12: 停滞
A13: 银/钯/钌 +20% | B13: +18% | C13: +30% | D13: +42%
A14: 银/钯/钌 +10% | B14: +12% | C14: +22% | D14: +34%
A15: 银/钯/钌 持平 (基准) | B15: +8% | C15: +18% | D15: +28%
A16: 银/钯/钌 -10% | B16: +3% | C16: +12% | D16: +22%
A17: 银/钯/钌 -20% | B17: -2% | C17: +6% | D17: +15%
A19: • 弹性观察一：产能兑现是2026缺口最大变量。若Murata/SEMCO扩产按100%兑现，缺口可缩窄至-10亿颗；若仅完成60%，缺口扩至-25亿颗。
A20: • 弹性观察二：AI capex弹性系数约为0.7。capex每增加10pp，MLCC需求增加约6.5亿颗。
A21: • 弹性观察三：国产替代是中长期最重要的变量。若三环、风华2027年实现0603 22μF X7R规模量产，价格曲线下行幅度可达10-15pp。
A22: • 弹性观察四：贵金属价格变化对均价影响约30-40%传导效率，主要影响中低端料号，对最高端AI料号影响有限。

Sheet 12_Investment_Map
A1: 标的弹性测算 v2.0（修正版：纳入现货vs出厂传导时滞、挤出折扣、扩产风险）
A2: 基于中性情景，量化各龙头2026-2028年AIDC业务收入贡献与EPS弹性
A4: 海外龙头
A5: 公司 | B5: 代码 | C5: AIDC核心产品 | D5: 2025 AIDC占收入(估) | E5: 2026 AIDC收入弹性 | F5: 2026 EPS弹性 | G5: PE区间(2026E) | H5: 评级
A6: Murata（村田） | B6: TYO:6981 | C6: MLCC、滤波器、电感 | D6: 12% | E6: +25% | F6: +45% | G6: 20-26x | H6: 增持
A7: 三星电机SEMCO | B7: KRX:009150 | C7: MLCC、玻璃基板、硅电容 | D7: 20% | E7: +40% | F7: +85% | G7: 15-22x | H7: 强烈推荐
A8: Taiyo Yuden | B8: TYO:6976 | C8: 高频MLCC、电感 | D8: 10% | E8: +20% | F8: +35% | G8: 18-24x | H8: 增持
A9: TDK | B9: TYO:6762 | C9: 电感、磁性、薄膜、铝电解 | D9: 15% | E9: +22% | F9: +30% | G9: 16-22x | H9: 增持
A10: Yageo（国巨） | B10: TPE:2327 | C10: MLCC、电阻、Kemet | D10: 8% | E10: +15% | F10: +22% | G10: 14-20x | H10: 持有
A11: Vishay | B11: NYSE:VSH | C11: 电感IHLP、电阻、薄膜 | D11: 18% | E11: +25% | F11: +40% | G11: 18-25x | H11: 增持
A12: Vicor | B12: NASDAQ:VICR | C12: Factorized Power | D12: 60% | E12: +50% | F12: +90% | G12: 30-50x | H12: 强烈推荐
A13: Panasonic Industry | B13: TYO:6752 | C13: 钽聚合物、薄膜 | D13: 10% | E13: +18% | F13: +25% | G13: 12-18x | H13: 持有
A15: 国内龙头
A16: 公司 | B16: 代码 | C16: AIDC核心产品 | D16: 2025 AIDC占收入(估) | E16: 2026 AIDC收入弹性 | F16: 2026 EPS弹性 | G16: PE区间(2026E) | H16: 评级
A17: 三环集团 | B17: 300408.SZ | C17: MLCC、陶瓷封装、介质粉 | D17: 5% | E17: +30% | F17: +50% | G17: 30-45x | H17: 强烈推荐
A18: 风华高科 | B18: 000636.SZ | C18: MLCC、片阻、上游材料 | D18: 3% | E18: +20% | F18: +40% | G18: 25-40x | H18: 增持
A19: 顺络电子 | B19: 002138.SZ | C19: 功率电感、共模电感 | D19: 12% | E19: +50% | F19: +90% | G19: 35-55x | H19: 强烈推荐
A20: 江海股份 | B20: 002484.SZ | C20: 铝电解、薄膜、超容 | D20: 8% | E20: +30% | F20: +55% | G20: 20-30x | H20: 强烈推荐
A21: 法拉电子 | B21: 600563.SH | C21: 薄膜电容 | D21: 5% | E21: +35% | F21: +60% | G21: 22-32x | H21: 强烈推荐
A22: 国瓷材料 | B22: 300285.SZ | C22: BaTiO₃介质粉 | D22: 10% | E22: +40% | F22: +70% | G22: 30-45x | H22: 战略关注
A23: 铂科新材 | B23: 300811.SZ | C23: 金属软磁粉芯 | D23: 10% | E23: +45% | F23: +80% | G23: 30-45x | H23: 战略关注
A24: 麦捷科技 | B24: 300319.SZ | C24: 共模电感、射频电感 | D24: 8% | E24: +25% | F24: +40% | G24: 25-35x | H24: 持有
A25: 鸿远电子 | B25: 603267.SH | C25: 瓷介电容（军工） | D25: — | E25: +15% | F25: +22% | G25: 30-50x | H25: 持有
A26: 火炬电子 | B26: 603678.SH | C26: 瓷介+钽（军工） | D26: — | E26: +15% | F26: +20% | G26: 30-45x | H26: 持有
A28: 说明
A29: • AIDC收入占比为基于公司公告/调研估算，部分公司AIDC业务尚未单独披露
A30: • AIDC收入弹性 = AIDC业务量×单价同比 - AIDC业务在传统业务上的替代/挤占
A31: • EPS弹性 ≈ 收入弹性 × (1 + 毛利率改善) × (1 - 税率), 假设AIDC业务毛利率比公司均值高10pp
A32: • PE区间为2026年预期EPS对应估值区间，基于行业历史峰值与当前位置对比
A33: • 强烈推荐：AIDC核心受益+α明确；增持：行业β明显但α相对温和；持有：弹性有限或估值已反映
A34: • 本表仅为研究参考，不构成投资建议。建议结合具体季报数据动态调整
A36: v2.0 修正说明（与v1差异）
A37: 原v1.0判断 | B37: v2.0修正 | C37: 修正依据
A38: 顺络电子 EPS弹性+90% 强烈推荐 | B38: 顺络电子 EPS弹性+50% 增持（仅个股α） | C38: 电感行业供需未短缺(<100%利用率)，主业仍是电感非MLCC
A39: 风华高科消费类弹性+40% | B39: 风华高科消费类弹性+28%（×0.7折扣） | C39: 产线不可互转：日系闲置产能无法移转至消费产线
A40: 三环集团强烈推荐（无风险提示） | B40: 三环集团强烈推荐（补充扩产延期风险） | C40: 高容量MLCC扩产项目预计使用从2025/5延期至2027/5
A41: 仅含中游零部件标的 | B41: 新增上游材料层：博迁新材+洁美科技+商络电子 | C41: 上游受益于行业总量增长，确定性更高
A42: MLCC均价同比+20%（统一） | B42: 拆分：现货+20%、出厂+5-8%（2026年） | C42: 村田/三星受长单约束，正式提牌价更可能2027Q1
A45: 新增标的：上游材料 + 流通环节
A46: 公司 | B46: 代码 | C46: AIDC核心产品 | D46: AIDC占比 | E46: EPS弹性 | F46: 评级 | G46: 投资逻辑
...

Sheet 13_Spot_vs_OEM
A1: 现货价 vs 出厂价：传导时滞模型
A2: 纪要校准：原厂受长单约束、出厂价调整滞后于现货6-12个月。2026年现货涨价≠出厂涨价
A4: [A] MLCC 高端料号双轨价格曲线
A5: 指标 | B5: 2024 | C5: 2025 | D5: 2026E | E5: 2027E | F5: 2028E | G5: 口径 | H5: 可信度
A6: 现货均价同比 | B6: — | C6: +5% | D6: +20% | E6: +12% | F6: +5% | G6: 渠道实际成交价 | H6: B级（TrendForce）
A7: 出厂均价同比 | B7: — | C7: +0% | D7: +5-8% | E7: +15-25% | F7: +8-12% | G7: 原厂报价/长协价 | H7: B+级（村田管理层口径）
A8: 现货-出厂价差 | B8: — | C8: +5pp | D8: +12-15pp | E8: 持平/收窄 | F8: 收窄 | G8: 代理商利润空间 | H8: 推算
A9: —— 触发出厂价上调的条件 ——
A10: AI占村田出货量比重 | B10: <3% | C10: 5% | D10: 7-8% | E10: 10%（触发点） | F10: 12%+ | G10: 村田内部门槛 | H10: A级
A11: 原厂稼动率（高端MLCC） | B11: 70% | C11: 85% | D11: 90-95% | E11: 95%+ | F11: 95%+ | G11: Class 3/4料号 | H11: A级（Murata IR）
A12: 全链库存月数 | B12: 1.5 | C12: 1.0 | D12: 0.5-0.8 | E12: 0.5-1.0 | F12: 1.0-1.5 | G12: 原厂+渠道+客户 | H12: B级
A13: —— 投资含义 ——
A14: A股标的真实业绩弹性（vs现货涨幅） | B14: — | C14: 10% | D14: 30-40% | E14: 70-80% | F14: 80-90% | G14: 现货→长单合约的传导比例 | H14: 经验估算
A15: 代理商（商络）受益度 | B15: — | C15: 中 | D15: 高 | E15: 中 | F15: 低 | G15: 价差扩大窗口 | H15: 推算
A16: 原厂（村田/三星）受益度 | B16: — | C16: 低 | D16: 中 | E16: 高 | F16: 高 | G16: 出厂价正式上调 | H16: 推算
A19: [B] 价格传导链阶段分析
A20: 阶段 | B20: 时间窗 | C20: 现货价 | D20: 出厂价 | E20: 原厂行为 | F20: 代理商 | G20: A股表现
A21: 阶段1：现货先涨 | B21: 2025H2-2026H1 | C21: +15-25% | D21: +0-5% | E21: 拒单、限量、长单优先 | F21: 库存浮盈、价差扩大 | G21: 情绪驱动板块上涨5-15%脉冲
A22: 阶段2：长单到期 | B22: 2026Q3-2027Q1 | C22: +30-40% | D22: +5-8% | E22: 新长单价格上调 | F22: 价差收窄 | G22: 毛利率改善预期发酵
A23: 阶段3：正式提牌价 | B23: 2027Q1-2027Q3 | C23: +30-50% | D23: +15-25% | E23: 全面调价 | F23: 价差进一步收窄 | G23: 业绩兑现+估值切换
A24: 阶段4：扩产消化 | B24: 2027H2-2028 | C24: +20-25% | D24: +15-20% | E24: 新产能投产 | F24: 价差恢复 | G24: 高位震荡、需观察拐点
A27: • 关键纪要观点：村田出厂价大幅调整需要AI占村田出货量从当前5%翻倍至10%，对应时点2027Q1。
A28: • 村田/三星电机 4月"涨价15-35%"消息为C+级（中文自媒体转引，无官方公告），不应作为A级事实。
A29: • A级数据底盘只有6条：村田AI MLCC需求强劲(IR)、村田高端稼动率90-95%(管理层)、
A30: • 村田AI 30% CAGR(IR)、三星电机Components业务2025创新高(财报)、三星考虑涨10%(业绩会)、Taiyo Yuden 5月涨6-13%(B+多家)。
A31: • 其余"事实"包括份额数字、单机用量、缺口测算等均为B级机构估算，需注明出处。

Sheet 14_Catalyst_Calendar
A1: 催化日历：5个关键事件节点 + 决策动作清单
A2: A股板块对海外催化反应即时（T+0或次日），通常给5-15%脉冲，1-2周内回吐一半
A4: [A] 关键事件时间轴
A5: 时间窗 | B5: 事件 | C5: 重要性 | D5: 正向解读 | E5: 负向解读 | F5: 决策动作
A6: 2026年3月底 | B6: 村田对AI服务器MLCC涨价决定 | C6: ★★★★★ | D6: 涨幅>20%：板块情绪点燃、加仓 | E6: 涨幅<10%：利好出尽、回调15-25%、减仓 | F6: 事件前1周降低beta，事件后24h确认幅度再调仓
A7: 2026年4月下-5月初 | B7: A股一季报披露 | C7: ★★★★★ | D7: 毛利率环比+2pp以上：真涨价兑现 | E7: 毛利率持平或下降：长单合约阻碍传导、估值回吐 | F7: 毛利率是真涨假涨的最关键指标，超预期则加仓三环/风华
A8: 2026Q2-Q3 | B8: AI服务器全链库存监测 | C8: ★★★★ | D8: 库存继续下行至0.3-0.5月：紧缺峰值 | E8: 库存回升至1.5月以上：周期翻转开始 | F8: 库存月数是最早的拐点信号，0.5以下则维持，1.5以上则减仓50%
A9: 2026Q4-2027Q1 | B9: AI占村田出货量是否达10% | C9: ★★★★★ | D9: 达到则村田正式提牌价（出厂价大幅上调） | E9: 未达则推迟，现货-出厂价差持续扩大但代理利润有限 | F9: 达到则切换到出厂价上涨情景，原厂直接受益的标的（村田、三星）超配
A10: 2027H2 | B10: 周期翻转监测 | C10: ★★★★ | D10: 扩产共识形成 + AI增速回落则周期顶部 | E10: AI需求继续强劲 + 扩产延期则缺口持续 | F10: 出现"原厂宣布加速扩产+台系率先降价+全链库存>1.5月"任两条则启动减仓流程
A13: [B] 板块脉冲实证数据（2025-2026）
A14: 时间 | B14: 海外触发事件 | C14: A股反应 | D14: 持续性
A15: 2025/7/19 | B15: 村田、TDK计划调涨20% | C15: 三环+9.8%创年内新高、洁美+7% | D15: 1-2日
A16: 2025/10/24 | B16: 国巨基美对钽电容涨价20-30% | C16: 宏达电子+10%、风华+火炬+三环跟涨 | D16: 2-3日
A17: 2026/2/1 | B17: 国巨、华新科涨价15-20%（电阻） | C17: 板块情绪升温但未涨停潮 | D17: 1-2日
A18: 2026/2/17 → 2/24 | B18: 村田计划AI MLCC涨价(2/17披露+2/24发酵) | C18: 昀冢科技20cm涨停、风华涨停、三环+16% | D18: 3-5日
A19: 2026年初至今 | B19: 整体涨价叙事发酵 | C19: 风华年内涨幅>26%、三环跑赢板块 | D19: 持续
A22: [C] 退出信号清单（任一出现则启动减仓流程）
A23: 编号 | B23: 退出信号 | C23: 信号源 | D23: 权重
A24: 1 | B24: 村田宣布加速扩产（突破10%/年的保守计划） | C24: 村田IR/季报 | D24: 高（结构性）
A25: 2 | B25: AI capex共识下修（北美云厂商财报集体下调指引） | C25: AWS/Microsoft/Google/Meta财报 | D25: 高（需求驱动）
A26: 3 | B26: 台系（国巨、华新科）率先降价 | C26: 公司公告/月度营收 | D26: 中（边际宽松信号）
A27: 4 | B27: MLCC全链库存回升至1.5月以上 | C27: TrendForce / 渠道调研 | D27: 高（周期反转）
A28: 5 | B28: 三环、风华季报毛利率连续两个季度环比下降 | C28: 公司季报 | D28: 高（业绩反转）

Sheet 15_Reverse_Scenario
A1: 反向情景：当涨价低于预期、消费拖累、台系降价时
A2: 正向研究易陷入确认偏误，本Sheet系统列出"催化失灵"情景的杀手与应对
A4: [A] 五大潜在杀手与影响测算
A5: 杀手 | B5: 触发条件 | C5: 概率 | D5: 对MLCC价格 | E5: 对A股标的 | F5: 应对动作
A6: 1. 村田涨价不及预期 | B6: 3月底涨价<10% | C6: 中-低 | D6: 现货溢价回吐10-15% | E6: 板块短期-15至-25% | F6: 降低高弹性标的（达利凯普、商络）50%
A7: 2. 长单合约阻碍传导 | B7: Q1季报毛利率持平 | C7: 中-高 | D7: 出厂价上行幅度受限 | E7: 估值回吐20% | F7: 保留基础仓位，减仓弹性头寸
A8: 3. 消费需求疲软延续 | B8: 台/中厂稼动率<70% | C8: 中 | D8: 挤出逻辑兑现度低 | E8: 风华、商络杀逻辑 | F8: 卖出偏消费标的、保留高端国产替代
A9: 4. 国产高端进度不达预期 | B9: 三环2025/5扩产再延期 | C9: 中-高 | D9: 国产替代故事打折 | E9: 三环估值-15% | F9: 三环减仓30%，加仓上游材料替代
A10: 5. AI capex放缓 | B10: 云厂商H2 capex下修>5% | C10: 低-中 | D10: 整产业链估值重估 | E10: 板块系统性-30% | F10: 全面减仓60%，转向防御标的
A13: [B] 反向情景下的标的安全边际矩阵
A14: 标的 | B14: 正向弹性(EPS) | C14: 杀手1+2情景 | D14: 杀手3情景 | E14: 杀手5情景 | F14: 综合安全边际
A15: 三环集团 | B15: +50% | C15: -20%（减仓30%） | D15: -15% | E15: -40% | F15: 中（高端确定性高，但扩产延期）
A16: 风华高科 | B16: +28% | C16: -25% | D16: -30%（消费拖累） | E16: -45% | F16: 低（消费暴露大）
A17: 顺络电子 | B17: +50% | C17: -15%（机制5不受影响） | D17: -10% | E17: -50% | F17: 中
A18: 法拉电子 | B18: +60% | C18: -10%（HVDC独立逻辑） | D18: -5% | E18: -35% | F18: 高（HVDC不受MLCC影响）
A19: 江海股份 | B19: +55% | C19: -12% | D19: -15% | E19: -30% | F19: 高（多业务平台）
A20: 国瓷材料 | B20: +70% | C20: -15% | D20: -10% | E20: -40% | F20: 中-高（上游确定性）
A21: 博迁新材 | B21: +45% | C21: -8% | D21: -5% | E21: -35% | F21: 高（量增驱动）
A22: 洁美科技 | B22: +35% | C22: -5% | D22: -10% | E22: -30% | F22: 高（载带平台）
A23: 商络电子 | B23: +40% | C23: -30%（价差收窄） | D23: -25% | E23: -30% | F23: 低（杠杆敞口）
A24: 达利凯普 | B24: +60% | C24: -35% | D24: -25% | E24: -50% | F24: 极低（情绪驱动）
A27: [C] 安全边际最高的三个组合配置思路
A28: 组合 | B28: 底仓 | C28: 弹性 | D28: 防御 | E28: 适用环境
A29: 进攻型 | B29: 三环+顺络（40%） | C29: 法拉+江海+博迁（40%） | D29: 国瓷+洁美（20%） | E29: 村田涨价>20% + 一季报毛利率改善 → 此时加杠杆
A30: 平衡型 | B30: 三环+法拉+国瓷（45%） | C30: 顺络+江海+博迁（30%） | D30: 洁美+商络（25%） | E30: 中性情景下默认配置（当前推荐）
A31: 防御型 | B31: 国瓷+洁美+博迁（50%） | C31: 法拉+江海（30%） | D31: 持币观望（20%） | E31: 村田涨价<10%或一季报不及预期 → 切换

Sheet 16_Upstream_Targets
A1: 上游材料 + 流通环节专项分析
A2: 原v1.0模型仅含中游零部件标的，v2.0补充"上游卖水人"和"流通环节杠杆"两条逻辑
A4: [A] MLCC上游产业链结构
A5: 环节 | B5: 代表企业 | C5: 产品 | D5: AIDC受益度 | E5: 技术壁垒 | F5: 国产替代进度
A6: 介质粉（BT粉） | B6: 日本堺化学 | C6: BaTiO₃超细粉 | D6: 极高（量增受益） | E6: 极高（粒径50nm/CV<10%） | F6: 国瓷材料切入中
A7: 介质粉（BT粉） | B7: 国瓷材料 | C7: BaTiO₃粉 | D7: 极高 | E7: 国内唯一规模化 | F7: 已突破
A8: 内电极镍粉 | B8: 日本JFE/住友 | C8: 纳米镍粉 | D8: 高 | E8: 极高 | F8: 博迁新材切入中
A9: 内电极镍粉 | B9: 博迁新材 | C9: 纳米镍粉 | D9: 极高 | E9: 国内龙头 | F9: 已突破
A10: 端电极银钯浆 | B10: 贺利氏 | C10: 贵金属浆料 | D10: 高 | E10: 贵金属价格驱动 | F10: 国产化进展慢
A11: 流延膜/离型膜 | B11: 日本东丽 | C11: PET离型膜 | D11: 中-高 | E11: 中-高 | F11: 洁美科技逐步替代
A12: 流延膜/离型膜 | B12: 洁美科技 | C12: MLCC离型膜+载带 | D12: 极高 | E12: 国内龙头 | F12: 已突破
A13: MLCC载带 | B13: 洁美科技 | C13: MLCC载带 | D13: 极高 | E13: 国内龙头 | F13: 全球领先
A14: 代理商/分销 | B14: Avnet/Arrow/文晔/大联大 | C14: 全品类电子分销 | D14: 中 | E14: — | F14: 国内代理（商络等）填补国产替代空间
A15: 代理商/分销 | B15: 商络电子 | C15: 电子分销+MLCC库存 | D15: 高（价差扩大） | E15: — | F15: 国内代理龙头
A18: [B] 上游+流通标的详细弹性测算
A19: 公司 | B19: 代码 | C19: 核心产品 | D19: 2025E AIDC占比 | E19: 2026E 收入弹性 | F19: 2026E EPS弹性 | G19: PE区间 | H19: 评级 | I19: 杀手敏感度
A20: 国瓷材料 | B20: 300285.SZ | C20: BaTiO₃介质粉 | D20: 10% | E20: +40% | F20: +70% | G20: 30-45x | H20: 战略关注 | I20: 中（量增驱动）
A21: 博迁新材 | B21: 605376.SH | C21: 镍粉（MLCC内电极） | D21: 15% | E21: +25% | F21: +45% | G21: 25-40x | H21: 增持 | I21: 中（量增驱动）
A22: 洁美科技 | B22: 002859.SZ | C22: MLCC载带 + 离型膜 | D22: 20% | E22: +22% | F22: +35% | G22: 20-32x | H22: 增持 | I22: 低（量增确定性极高）
A23: 商络电子 | B23: 300975.SZ | C23: 电子分销代理 | D23: 10% | E23: +25% | F23: +40% | G23: 18-28x | H23: 增持 | I23: 高（杠杆敞口）
A24: 铂科新材 | B24: 300811.SZ | C24: 金属软磁粉芯 | D24: 10% | E24: +45% | F24: +80% | G24: 30-45x | H24: 战略关注 | I24: 中
A25: 立中集团 | B25: 300428.SZ | C25: MLCC合金材料 | D25: 5% | E25: +15% | F25: +25% | G25: 20-30x | H25: 持有 | I25: 中
A28: [C] 上游+流通标的的核心吸引力
A29: • 上游材料层（国瓷、博迁、洁美、铂科）：享受"行业总量增长"，不依赖具体客户胜出，确定性最高
A30: • 国瓷材料：是三星电机BT粉核心供应商，受益于三星扩产斜率（2025-2027 CAGR 32%）
A31: • 博迁新材：镍粉龙头，对MLCC行业总量极敏感，相比中游公司毛利率更稳定
A32: • 洁美科技：MLCC载带+离型膜双龙头，全球市场份额35%以上，量增直接传导
A33: • 商络电子：现货涨而出厂不涨情景下，代理商是第一受益人——库存浮盈+价差扩大
A34: • 铂科新材：金属软磁粉芯（电感关键磁性原料）龙头，受益于AI高频电感需求暴增
A35: • 组合配置：建议在原v1配置基础上，增加上游+流通占比至25-30%，作为防御性补强
